// Utility functions for API calls with proper error handling and retries

export interface RetryOptions {
  maxRetries?: number;
  delay?: number;
  backoff?: boolean;
}

export async function withRetry<T>(
  fn: () => Promise<T>,
  options: RetryOptions = {}
): Promise<T> {
  const { maxRetries = 2, delay = 1000, backoff = true } = options;
  
  let lastError: unknown;
  
  for (let attempt = 0; attempt <= maxRetries; attempt++) {
    try {
      return await fn();
    } catch (error) {
      lastError = error;
      
      if (attempt === maxRetries) {
        break;
      }
      
      const waitTime = backoff ? delay * Math.pow(2, attempt) : delay;
      await new Promise(resolve => setTimeout(resolve, waitTime));
    }
  }
  
  throw lastError;
}

export async function withTimeout<T>(
  promise: Promise<T>,
  timeoutMs: number,
  timeoutMessage = `Operation timed out after ${timeoutMs}ms`
): Promise<T> {
  const timeoutPromise = new Promise<never>((_, reject) => {
    setTimeout(() => reject(new Error(timeoutMessage)), timeoutMs);
  });
  
  return Promise.race([promise, timeoutPromise]);
}

export async function apiCallWithRetryAndTimeout<T>(
  apiCall: () => Promise<T>,
  timeoutMs = 30000,
  retryOptions: RetryOptions = {}
): Promise<T> {
  return withRetry(
    () => withTimeout(apiCall(), timeoutMs),
    retryOptions
  );
}